Workbook

Sheet По разделам
A1: Раздел | B1: Оборот, ₸ | C1: Доля | D1: Заказы, шт | E1: Ниш | F1: Средний чек, ₸
A2: Телефоны и гаджеты | B2: =SUMIFS('Все ниши'!$E$2:$E$2267,'Все ниши'!$C$2:$C$2267,A2) | C2: =B2/SUM($B$2:$B$20) | D2: =SUMIFS('Все ниши'!$F$2:$F$2267,'Все ниши'!$C$2:$C$2267,A2) | E2: =COUNTIF('Все ниши'!$C$2:$C$2267,A2) | F2: =IFERROR(B2/D2,0)
A3: Бытовая техника | B3: =SUMIFS('Все ниши'!$E$2:$E$2267,'Все ниши'!$C$2:$C$2267,A3) | C3: =B3/SUM($B$2:$B$20) | D3: =SUMIFS('Все ниши'!$F$2:$F$2267,'Все ниши'!$C$2:$C$2267,A3) | E3: =COUNTIF('Все ниши'!$C$2:$C$2267,A3) | F3: =IFERROR(B3/D3,0)
A4: Мебель | B4: =SUMIFS('Все ниши'!$E$2:$E$2267,'Все ниши'!$C$2:$C$2267,A4) | C4: =B4/SUM($B$2:$B$20) | D4: =SUMIFS('Все ниши'!$F$2:$F$2267,'Все ниши'!$C$2:$C$2267,A4) | E4: =COUNTIF('Все ниши'!$C$2:$C$2267,A4) | F4: =IFERROR(B4/D4,0)
A5: Красота и здоровье | B5: =SUMIFS('Все ниши'!$E$2:$E$2267,'Все ниши'!$C$2:$C$2267,A5) | C5: =B5/SUM($B$2:$B$20) | D5: =SUMIFS('Все ниши'!$F$2:$F$2267,'Все ниши'!$C$2:$C$2267,A5) | E5: =COUNTIF('Все ниши'!$C$2:$C$2267,A5) | F5: =IFERROR(B5/D5,0)
A6: Товары для дома и дачи | B6: =SUMIFS('Все ниши'!$E$2:$E$2267,'Все ниши'!$C$2:$C$2267,A6) | C6: =B6/SUM($B$2:$B$20) | D6: =SUMIFS('Все ниши'!$F$2:$F$2267,'Все ниши'!$C$2:$C$2267,A6) | E6: =COUNTIF('Все ниши'!$C$2:$C$2267,A6) | F6: =IFERROR(B6/D6,0)
A7: Компьютеры | B7: =SUMIFS('Все ниши'!$E$2:$E$2267,'Все ниши'!$C$2:$C$2267,A7) | C7: =B7/SUM($B$2:$B$20) | D7: =SUMIFS('Все ниши'!$F$2:$F$2267,'Все ниши'!$C$2:$C$2267,A7) | E7: =COUNTIF('Все ниши'!$C$2:$C$2267,A7) | F7: =IFERROR(B7/D7,0)
A8: Автотовары | B8: =SUMIFS('Все ниши'!$E$2:$E$2267,'Все ниши'!$C$2:$C$2267,A8) | C8: =B8/SUM($B$2:$B$20) | D8: =SUMIFS('Все ниши'!$F$2:$F$2267,'Все ниши'!$C$2:$C$2267,A8) | E8: =COUNTIF('Все ниши'!$C$2:$C$2267,A8) | F8: =IFERROR(B8/D8,0)
A9: Аптека | B9: =SUMIFS('Все ниши'!$E$2:$E$2267,'Все ниши'!$C$2:$C$2267,A9) | C9: =B9/SUM($B$2:$B$20) | D9: =SUMIFS('Все ниши'!$F$2:$F$2267,'Все ниши'!$C$2:$C$2267,A9) | E9: =COUNTIF('Все ниши'!$C$2:$C$2267,A9) | F9: =IFERROR(B9/D9,0)
A10: ТВ, Аудио, Видео | B10: =SUMIFS('Все ниши'!$E$2:$E$2267,'Все ниши'!$C$2:$C$2267,A10) | C10: =B10/SUM($B$2:$B$20) | D10: =SUMIFS('Все ниши'!$F$2:$F$2267,'Все ниши'!$C$2:$C$2267,A10) | E10: =COUNTIF('Все ниши'!$C$2:$C$2267,A10) | F10: =IFERROR(B10/D10,0)
A11: Строительство, ремонт | B11: =SUMIFS('Все ниши'!$E$2:$E$2267,'Все ниши'!$C$2:$C$2267,A11) | C11: =B11/SUM($B$2:$B$20) | D11: =SUMIFS('Все ниши'!$F$2:$F$2267,'Все ниши'!$C$2:$C$2267,A11) | E11: =COUNTIF('Все ниши'!$C$2:$C$2267,A11) | F11: =IFERROR(B11/D11,0)
A12: Спорт, туризм | B12: =SUMIFS('Все ниши'!$E$2:$E$2267,'Все ниши'!$C$2:$C$2267,A12) | C12: =B12/SUM($B$2:$B$20) | D12: =SUMIFS('Все ниши'!$F$2:$F$2267,'Все ниши'!$C$2:$C$2267,A12) | E12: =COUNTIF('Все ниши'!$C$2:$C$2267,A12) | F12: =IFERROR(B12/D12,0)
A13: Украшения | B13: =SUMIFS('Все ниши'!$E$2:$E$2267,'Все ниши'!$C$2:$C$2267,A13) | C13: =B13/SUM($B$2:$B$20) | D13: =SUMIFS('Все ниши'!$F$2:$F$2267,'Все ниши'!$C$2:$C$2267,A13) | E13: =COUNTIF('Все ниши'!$C$2:$C$2267,A13) | F13: =IFERROR(B13/D13,0)
... A20: Канцелярские товары | B20: =SUMIFS('Все ниши'!$E$2:$E$2267,'Все ниши'!$C$2:$C$2267,A20) | C20: =B20/SUM($B$2:$B$20) | D20: =SUMIFS('Все ниши'!$F$2:$F$2267,'Все ниши'!$C$2:$C$2267,A20) | E20: =COUNTIF('Все ниши'!$C$2:$C$2267,A20) | F20: =IFERROR(B20/D20,0)
A21: ИТОГО | B21: =SUM(B2:B20) | C21: =SUM(C2:C20) | D21: =SUM(D2:D20) | E21: =SUM(E2:E20) | F21: =IFERROR(B21/D21,0)
A23: Источник: RedStat (аналитика Kaspi.kz), период — август 2026 (календарный месяц), метрика — выручка (sale_amount). Все суммы в тенге.

Sheet Все ниши
A1: № | B1: Ниша | C1: Раздел | D1: Путь в каталоге | E1: Оборот, ₸ | F1: Заказы, шт | G1: Средний чек, ₸ | H1: SKU, шт | I1: Брендов | J1: Выручка на SKU, ₸ | K1: Доля рынка | L1: Накопл. доля | M1: ID ниши | N1: RedStat | O1: Kaspi
A2: 1 | B2: Смартфоны | C2: Телефоны и гаджеты | D2: Телефоны и гаджеты → Смартфоны | E2: 40740351810 | F2: 110088 | G2: =IFERROR(E2/F2,0) | H2: 3302 | I2: 36 | J2: =IFERROR(E2/H2,0) | K2: =E2/'По разделам'!$B$21 | L2: =K2 | M2: 00003 | N2: https://app.redstat.kz/niche/00003?event_date=2026-08-01 | O2: https://kaspi.kz/shop/c/smartphones/
A3: 2 | B3: Витамины и БАД | C3: Аптека | D3: Аптека → Витамины и БАД | E3: 9516905073 | F3: 1381320 | G3: =IFERROR(E3/F3,0) | H3: 18879 | I3: 1795 | J3: =IFERROR(E3/H3,0) | K3: =E3/'По разделам'!$B$21 | L3: =L2+K3 | M3: 04550 | N3: https://app.redstat.kz/niche/04550?event_date=2026-08-01 | O3: https://kaspi.kz/shop/c/vitamins/
A4: 3 | B4: Ноутбуки | C4: Компьютеры | D4: Компьютеры → Ноутбуки и аксессуары → Ноутбуки | E4: 5965719185 | F4: 16459 | G4: =IFERROR(E4/F4,0) | H4: 1811 | I4: 78 | J4: =IFERROR(E4/H4,0) | K4: =E4/'По разделам'!$B$21 | L4: =L3+K4 | M4: 00588 | N4: https://app.redstat.kz/niche/00588?event_date=2026-08-01 | O4: https://kaspi.kz/shop/c/notebooks/
A5: 4 | B5: Холодильники | C5: Бытовая техника | D5: Бытовая техника → Крупная техника для дома → Холодильники | E5: 3728770671 | F5: 17448 | G5: =IFERROR(E5/F5,0) | H5: 1187 | I5: 88 | J5: =IFERROR(E5/H5,0) | K5: =E5/'По разделам'!$B$21 | L5: =L4+K5 | M5: 00025 | N5: https://app.redstat.kz/niche/00025?event_date=2026-08-01 | O5: https://kaspi.kz/shop/c/refrigerators/
A6: 5 | B6: Стиральные машины | C6: Бытовая техника | D6: Бытовая техника → Крупная техника для дома → Стиральные машины | E6: 3472279970 | F6: 20601 | G6: =IFERROR(E6/F6,0) | H6: 939 | I6: 99 | J6: =IFERROR(E6/H6,0) | K6: =E6/'По разделам'!$B$21 | L6: =L5+K6 | M6: 00035 | N6: https://app.redstat.kz/niche/00035?event_date=2026-08-01 | O6: https://kaspi.kz/shop/c/washers/
A7: 6 | B7: Шины для легковых и внедорожных автомобилей | C7: Автотовары | D7: Автотовары → Шины → Шины для легковых и внедорожных автомобилей | E7: 3323820614 | F7: 28278 | G7: =IFERROR(E7/F7,0) | H7: 8227 | I7: 209 | J7: =IFERROR(E7/H7,0) | K7: =E7/'По разделам'!$B$21 | L7: =L6+K7 | M7: 02640 | N7: https://app.redstat.kz/niche/02640?event_date=2026-08-01 | O7: https://kaspi.kz/shop/c/passenger%20car%20tires/
A8: 7 | B8: Пылесосы | C8: Бытовая техника | D8: Бытовая техника → Малая техника для дома → Пылесосы | E8: 2473506910 | F8: 98084 | G8: =IFERROR(E8/F8,0) | H8: 1937 | I8: 429 | J8: =IFERROR(E8/H8,0) | K8: =E8/'По разделам'!$B$21 | L8: =L7+K8 | M8: 00036 | N8: https://app.redstat.kz/niche/00036?event_date=2026-08-01 | O8: https://kaspi.kz/shop/c/vacuum%20cleaners/
A9: 8 | B9: Телевизоры | C9: ТВ, Аудио, Видео | D9: ТВ, Аудио, Видео → Телевизоры | E9: 2343539408 | F9: 12873 | G9: =IFERROR(E9/F9,0) | H9: 900 | I9: 91 | J9: =IFERROR(E9/H9,0) | K9: =E9/'По разделам'!$B$21 | L9: =L8+K9 | M9: 05374 | N9: https://app.redstat.kz/niche/05374?event_date=2026-08-01 | O9: https://kaspi.kz/shop/c/tvs/
A10: 9 | B10: Диваны и комплекты мягкой мебели | C10: Мебель | D10: Мебель → Гостиная → Диваны и комплекты мягкой мебели | E10: 2287100456 | F10: 18456 | G10: =IFERROR(E10/F10,0) | H10: 2718 | I10: 268 | J10: =IFERROR(E10/H10,0) | K10: =E10/'По разделам'!$B$21 | L10: =L9+K10 | M10: 00562 | N10: https://app.redstat.kz/niche/00562?event_date=2026-08-01 | O10: https://kaspi.kz/shop/c/sofas/
A11: 10 | B11: Планшеты | C11: Компьютеры | D11: Компьютеры → Планшеты и аксессуары → Планшеты | E11: 2036218563 | F11: 12214 | G11: =IFERROR(E11/F11,0) | H11: 844 | I11: 92 | J11: =IFERROR(E11/H11,0) | K11: =E11/'По разделам'!$B$21 | L11: =L10+K11 | M11: 01325 | N11: https://app.redstat.kz/niche/01325?event_date=2026-08-01 | O11: https://kaspi.kz/shop/c/tablets/
A12: 11 | B12: Шкафы для одежды | C12: Мебель | D12: Мебель → Спальня → Шкафы для одежды | E12: 1981417411 | F12: 19254 | G12: =IFERROR(E12/F12,0) | H12: 2694 | I12: 243 | J12: =IFERROR(E12/H12,0) | K12: =E12/'По разделам'!$B$21 | L12: =L11+K12 | M12: 00316 | N12: https://app.redstat.kz/niche/00316?event_date=2026-08-01 | O12: https://kaspi.kz/shop/c/wardrobes/
A13: 12 | B13: Морозильники | C13: Бытовая техника | D13: Бытовая техника → Крупная техника для дома → Морозильники | E13: 1815575249 | F13: 13648 | G13: =IFERROR(E13/F13,0) | H13: 652 | I13: 81 | J13: =IFERROR(E13/H13,0) | K13: =E13/'По разделам'!$B$21 | L13: =L12+K13 | M13: 00026 | N13: https://app.redstat.kz/niche/00026?event_date=2026-08-01 | O13: https://kaspi.kz/shop/c/freezers/
A14: 13 | B14: Кондиционеры | C14: Бытовая техника | D14: Бытовая техника → Климатическая техника → Кондиционеры | E14: 1794465081 | F14: 9994 | G14: =IFERROR(E14/F14,0) | H14: 848 | I14: 99 | J14: =IFERROR(E14/H14,0) | K14: =E14/'По разделам'!$B$21 | L14: =L13+K14 | M14: 00047 | N14: https://app.redstat.kz/niche/00047?event_date=2026-08-01 | O14: https://kaspi.kz/shop/c/air%20conditioners/
... A19: 18 | B19: Парфюмерия | C19: Красота и здоровье | D19: Красота и здоровье → Парфюмерия | E19: 1359807981 | F19: 122812 | G19: =IFERROR(E19/F19,0) | H19: 11822 | I19: 755 | J19: =IFERROR(E19/H19,0) | K19: =E19/'По разделам'!$B$21 | L19: =L18+K19 | M19: 00563 | N19: https://app.redstat.kz/niche/00563?event_date=2026-08-01 | O19: https://kaspi.kz/shop/c/perfumes/
A20: 19 | B20: Печи и грили | C20: Бытовая техника | D20: Бытовая техника → Мелкая техника для кухни → Печи и грили → Печи и грили | E20: 1287669658 | F20: 44994 | G20: =IFERROR(E20/F20,0) | H20: 1774 | I20: 369 | J20: =IFERROR(E20/H20,0) | K20: =E20/'По разделам'!$B$21 | L20: =L19+K20 | M20: q86fab4ff138e681 | N20: https://app.redstat.kz/niche/q86fab4ff138e681?event_date=2026-08-01
A21: 20 | B21: Системные блоки | C21: Компьютеры | D21: Компьютеры → Настольные компьютеры → Системные блоки | E21: 1098686317 | F21: 2136 | G21: =IFERROR(E21/F21,0) | H21: 600 | I21: 96 | J21: =IFERROR(E21/H21,0) | K21: =E21/'По разделам'!$B$21 | L21: =L20+K21 | M21: 05403 | N21: https://app.redstat.kz/niche/05403?event_date=2026-08-01 | O21: https://kaspi.kz/shop/c/desktops/
A22: 21 | B22: Садовая техника | C22: Товары для дома и дачи | D22: Товары для дома и дачи → Дача, сад и огород → Садовая техника → Садовая техника | E22: 1028872096 | F22: 23419 | G22: =IFERROR(E22/F22,0) | H22: 3893 | I22: 448 | J22: =IFERROR(E22/H22,0) | K22: =E22/'По разделам'!$B$21 | L22: =L21+K22 | M22: qb71a7a07068894e | N22: https://app.redstat.kz/niche/qb71a7a07068894e?event_date=2026-08-01
A23: 22 | B23: Кольца ювелирные | C23: Украшения | D23: Украшения → Кольца → Кольца ювелирные | E23: 1013930477 | F23: 23440 | G23: =IFERROR(E23/F23,0) | H23: 6629 | I23: 497 | J23: =IFERROR(E23/H23,0) | K23: =E23/'По разделам'!$B$21 | L23: =L22+K23 | M23: 00743 | N23: https://app.redstat.kz/niche/00743?event_date=2026-08-01 | O23: https://kaspi.kz/shop/c/rings/
A24: 23 | B24: Комплекты ювелирных украшений | C24: Украшения | D24: Украшения → Комплекты украшений → Комплекты ювелирных украшений | E24: 994048454 | F24: 10855 | G24: =IFERROR(E24/F24,0) | H24: 1838 | I24: 361 | J24: =IFERROR(E24/H24,0) | K24: =E24/'По разделам'!$B$21 | L24: =L23+K24 | M24: 01246 | N24: https://app.redstat.kz/niche/01246?event_date=2026-08-01 | O24: https://kaspi.kz/shop/c/jewelry%20sets/
A25: 24 | B25: Посуда для приготовления | C25: Товары для дома и дачи | D25: Товары для дома и дачи → Посуда и принадлежности → Посуда для приготовления → Посуда для приготовления | E25: 974719576 | F25: 88120 | G25: =IFERROR(E25/F25,0) | H25: 8566 | I25: 653 | J25: =IFERROR(E25/H25,0) | K25: =E25/'По разделам'!$B$21 | L25: =L24+K25 | M25: qd8920d58c7de0d8 | N25: https://app.redstat.kz/niche/qd8920d58c7de0d8?event_date=2026-08-01
A26: 25 | B26: Матрасы | C26: Мебель | D26: Мебель → Спальня → Матрасы | E26: 955552735 | F26: 18113 | G26: =IFERROR(E26/F26,0) | H26: 3302 | I26: 221 | J26: =IFERROR(E26/H26,0) | K26: =E26/'По разделам'!$B$21 | L26: =L25+K26 | M26: 00317 | N26: https://app.redstat.kz/niche/00317?event_date=2026-08-01 | O26: https://kaspi.kz/shop/c/bedroom%20mattresses/
A27: 26 | B27: Серьги ювелирные | C27: Украшения | D27: Украшения → Серьги → Серьги ювелирные | E27: 954633475 | F27: 25069 | G27: =IFERROR(E27/F27,0) | H27: 5310 | I27: 481 | J27: =IFERROR(E27/H27,0) | K27: =E27/'По разделам'!$B$21 | L27: =L26+K27 | M27: 00744 | N27: https://app.redstat.kz/niche/00744?event_date=2026-08-01 | O27: https://kaspi.kz/shop/c/earrings/
A28: 27 | B28: Шины для грузового транспорта и спецтехники | C28: Автотовары | D28: Автотовары → Шины → Шины для грузового транспорта и спецтехники | E28: 952049889 | F28: 2729 | G28: =IFERROR(E28/F28,0) | H28: 887 | I28: 110 | J28: =IFERROR(E28/H28,0) | K28: =E28/'По разделам'!$B$21 | L28: =L27+K28 | M28: 02634 | N28: https://app.redstat.kz/niche/02634?event_date=2026-08-01 | O28: https://kaspi.kz/shop/c/heavy%20duty%20tires/
A29: 28 | B29: Прочая кухонная техника | C29: Бытовая техника | D29: Бытовая техника → Мелкая техника для кухни → Прочая кухонная техника → Прочая кухонная техника | E29: 917853483 | F29: 31743 | G29: =IFERROR(E29/F29,0) | H29: 1952 | I29: 476 | J29: =IFERROR(E29/H29,0) | K29: =E29/'По разделам'!$B$21 | L29: =L28+K29 | M29: qd9b3ff4ab6368a3 | N29: https://app.redstat.kz/niche/qd9b3ff4ab6368a3?event_date=2026-08-01
A30: 29 | B30: Цепи ювелирные | C30: Украшения | D30: Украшения → Цепи → Цепи ювелирные | E30: 887209104 | F30: 13442 | G30: =IFERROR(E30/F30,0) | H30: 1979 | I30: 285 | J30: =IFERROR(E30/H30,0) | K30: =E30/'По разделам'!$B$21 | L30: =L29+K30 | M30: 01753 | N30: https://app.redstat.kz/niche/01753?event_date=2026-08-01 | O30: https://kaspi.kz/shop/c/necklaces/
A31: 30 | B31: Отопительные котлы | C31: Бытовая техника | D31: Бытовая техника → Отопительные котлы | E31: 850050389 | F31: 3103 | G31: =IFERROR(E31/F31,0) | H31: 748 | I31: 121 | J31: =IFERROR(E31/H31,0) | K31: =E31/'По разделам'!$B$21 | L31: =L30+K31 | M31: 00103 | N31: https://app.redstat.kz/niche/00103?event_date=2026-08-01 | O31: https://kaspi.kz/shop/c/boilers/
A32: 31 | B32: Обеденные группы | C32: Мебель | D32: Мебель → Кухня → Обеденные группы | E32: 832802690 | F32: 7545 | G32: =IFERROR(E32/F32,0) | H32: 879 | I32: 106 | J32: =IFERROR(E32/H32,0) | K32: =E32/'По разделам'!$B$21 | L32: =L31+K32 | M32: 05356 | N32: https://app.redstat.kz/niche/05356?event_date=2026-08-01 | O32: https://kaspi.kz/shop/c/dining%20sets/
A33: 32 | B33: Принтеры и МФУ | C33: Компьютеры | D33: Компьютеры → Оргтехника и расходные материалы → Принтеры и МФУ | E33: 822123414 | F33: 8129 | G33: =IFERROR(E33/F33,0) | H33: 259 | I33: 14 | J33: =IFERROR(E33/H33,0) | K33: =E33/'По разделам'!$B$21 | L33: =L32+K33 | M33: 02930 | N33: https://app.redstat.kz/niche/02930?event_date=2026-08-01 | O33: https://kaspi.kz/shop/c/mf%20printers/
A34: 33 | B34: Уход и гигиена малыша | C34: Детские товары | D34: Детские товары → Для малыша и мамы → Уход и гигиена малыша → Уход и гигиена малыша | E34: 800773333 | F34: 146334 | G34: =IFERROR(E34/F34,0) | H34: 4254 | I34: 549 | J34: =IFERROR(E34/H34,0) | K34: =E34/'По разделам'!$B$21 | L34: =L33+K34 | M34: qcd099c503c60396 | N34: https://app.redstat.kz/niche/qcd099c503c60396?event_date=2026-08-01
A35: 34 | B35: Кухонные комбайны и мясорубки | C35: Бытовая техника | D35: Бытовая техника → Мелкая техника для кухни → Кухонные комбайны и мясорубки → Кухонные комбайны и мясорубки | E35: 798796434 | F35: 14868 | G35: =IFERROR(E35/F35,0) | H35: 742 | I35: 256 | J35: =IFERROR(E35/H35,0) | K35: =E35/'По разделам'!$B$21 | L35: =L34+K35 | M35: qd834b46d8028604 | N35: https://app.redstat.kz/niche/qd834b46d8028604?event_date=2026-08-01
A36: 35 | B36: Духовые шкафы | C36: Бытовая техника | D36: Бытовая техника → Крупная техника для дома → Духовые шкафы | E36: 781589566 | F36: 4242 | G36: =IFERROR(E36/F36,0) | H36: 578 | I36: 59 | J36: =IFERROR(E36/H36,0) | K36: =E36/'По разделам'!$B$21 | L36: =L35+K36 | M36: 00023 | N36: https://app.redstat.kz/niche/00023?event_date=2026-08-01 | O36: https://kaspi.kz/shop/c/ovens/
A37: 36 | B37: Компьютерные и письменные столы | C37: Мебель | D37: Мебель → Офис и кабинет → Компьютерные и письменные столы | E37: 768924023 | F37: 23078 | G37: =IFERROR(E37/F37,0) | H37: 1446 | I37: 208 | J37: =IFERROR(E37/H37,0) | K37: =E37/'По разделам'!$B$21 | L37: =L36+K37 | M37: 05353 | N37: https://app.redstat.kz/niche/05353?event_date=2026-08-01 | O37: https://kaspi.kz/shop/c/computer%20desks/
A38: 37 | B38: Наборы косметики | C38: Красота и здоровье | D38: Красота и здоровье → Наборы косметики | E38: 733174940 | F38: 72382 | G38: =IFERROR(E38/F38,0) | H38: 3742 | I38: 602 | J38: =IFERROR(E38/H38,0) | K38: =E38/'По разделам'!$B$21 | L38: =L37+K38 | M38: 07146 | N38: https://app.redstat.kz/niche/07146?event_date=2026-08-01 | O38: https://kaspi.kz/shop/c/cosmetics%20sets/
A39: 38 | B39: Сумки | C39: Аксессуары | D39: Аксессуары → Сумки, чемоданы, кошельки → Сумки | E39: 725232276 | F39: 158611 | G39: =IFERROR(E39/F39,0) | H39: 8285 | I39: 817 | J39: =IFERROR(E39/H39,0) | K39: =E39/'По разделам'!$B$21 | L39: =L38+K39 | M39: 01770 | N39: https://app.redstat.kz/niche/01770?event_date=2026-08-01 | O39: https://kaspi.kz/shop/c/fashion%20handbags/
A40: 39 | B40: Столовая посуда | C40: Товары для дома и дачи | D40: Товары для дома и дачи → Посуда и принадлежности → Столовая посуда → Столовая посуда | E40: 707606915 | F40: 64517 | G40: =IFERROR(E40/F40,0) | H40: 9768 | I40: 736 | J40: =IFERROR(E40/H40,0) | K40: =E40/'По разделам'!$B$21 | L40: =L39+K40 | M40: q374f64c9f962207 | N40: https://app.redstat.kz/niche/q374f64c9f962207?event_date=2026-08-01
A41: 40 | B41: Электроинструменты | C41: Строительство, ремонт | D41: Строительство, ремонт → Инструменты → Электроинструменты → Электроинструменты | E41: 684444805 | F41: 23319 | G41: =IFERROR(E41/F41,0) | H41: 3050 | I41: 376 | J41: =IFERROR(E41/H41,0) | K41: =E41/'По разделам'!$B$21 | L41: =L40+K41 | M41: q42b272690abdb84 | N41: https://app.redstat.kz/niche/q42b272690abdb84?event_date=2026-08-01
A42: 41 | B42: Водонагреватели | C42: Бытовая техника | D42: Бытовая техника → Климатическая техника → Водонагреватели | E42: 682517851 | F42: 11629 | G42: =IFERROR(E42/F42,0) | H42: 844 | I42: 102 | J42: =IFERROR(E42/H42,0) | K42: =E42/'По разделам'!$B$21 | L42: =L41+K42 | M42: 00040 | N42: https://app.redstat.kz/niche/00040?event_date=2026-08-01 | O42: https://kaspi.kz/shop/c/water%20heaters/
A43: 42 | B43: Кухонные гарнитуры | C43: Мебель | D43: Мебель → Кухня → Кухонные гарнитуры | E43: 680827067 | F43: 4353 | G43: =IFERROR(E43/F43,0) | H43: 716 | I43: 94 | J43: =IFERROR(E43/H43,0) | K43: =E43/'По разделам'!$B$21 | L43: =L42+K43 | M43: 00772 | N43: https://app.redstat.kz/niche/00772?event_date=2026-08-01 | O43: https://kaspi.kz/shop/c/kitchen%20sets/
A44: 43 | B44: Фены | C44: Красота и здоровье | D44: Красота и здоровье → Техника и оборудование для красоты → Фены | E44: 672219305 | F44: 31097 | G44: =IFERROR(E44/F44,0) | H44: 1734 | I44: 410 | J44: =IFERROR(E44/H44,0) | K44: =E44/'По разделам'!$B$21 | L44: =L43+K44 | M44: 06220 | N44: https://app.redstat.kz/niche/06220?event_date=2026-08-01 | O44: https://kaspi.kz/shop/c/hair%20dryers/
...
